2019-07-15 22:10:15 - recv_consumer - 7953 - ERROR : 非法状态 ---> [recv_consumer.py:789 process_tasks]
2019-07-15 22:10:15 - recv_consumer - 7953 - ERROR : 不关心的状态 ---> [recv_consumer.py:818 process_tasks]
2019-07-15 22:11:00 - recv_consumer - 7953 - ERROR : 
Traceback (most recent call last):
  File "/home/zzc/docker_test/app/fq-trainbox/fq_task_recv/DockerApp/recv_consumer.py", line 300, in download_files
    info = self.client.get_task_info(self.task['id'])
  File "/home/zzc/anaconda3/envs/python3.6/lib/python3.6/site-packages/mock/mock.py", line 1092, in __call__
    return _mock_self._mock_call(*args, **kwargs)
  File "/home/zzc/anaconda3/envs/python3.6/lib/python3.6/site-packages/mock/mock.py", line 1147, in _mock_call
    raise result
Exception

 ---> [recv_consumer.py:306 download_files]
2019-07-15 22:11:24 - recv_consumer - 7953 - ERROR : 
Traceback (most recent call last):
  File "/home/zzc/docker_test/app/fq-trainbox/fq_task_recv/DockerApp/recv_consumer.py", line 267, in run_script_in_container
    time.sleep(2)
KeyboardInterrupt

 ---> [recv_consumer.py:272 run_script_in_container]
2019-07-15 22:11:24 - recv_consumer - 7953 - ERROR : 
Traceback (most recent call last):
  File "/home/zzc/docker_test/app/fq-trainbox/fq_task_recv/DockerApp/recv_consumer.py", line 257, in run_script_in_container
    cont_id = os.popen(docker_cmd).read().split('\n')[0][:10]
KeyboardInterrupt

 ---> [recv_consumer.py:272 run_script_in_container]
2019-07-15 22:11:24 - recv_consumer - 7953 - ERROR : 
Traceback (most recent call last):
  File "/home/zzc/docker_test/app/fq-trainbox/fq_task_recv/DockerApp/recv_consumer.py", line 276, in run_script_in_container
    cont_id=cont_id)
UnboundLocalError: local variable 'cont_id' referenced before assignment

 ---> [recv_consumer.py:282 run_script_in_container]
2019-07-15 22:13:17 - recv_consumer - 8628 - ERROR : 非法状态 ---> [recv_consumer.py:789 process_tasks]
2019-07-15 22:13:17 - recv_consumer - 8628 - ERROR : 不关心的状态 ---> [recv_consumer.py:818 process_tasks]
2019-07-15 22:14:01 - recv_consumer - 8628 - ERROR : 
Traceback (most recent call last):
  File "/home/zzc/docker_test/app/fq-trainbox/fq_task_recv/DockerApp/recv_consumer.py", line 300, in download_files
    info = self.client.get_task_info(self.task['id'])
  File "/home/zzc/anaconda3/envs/python3.6/lib/python3.6/site-packages/mock/mock.py", line 1092, in __call__
    return _mock_self._mock_call(*args, **kwargs)
  File "/home/zzc/anaconda3/envs/python3.6/lib/python3.6/site-packages/mock/mock.py", line 1147, in _mock_call
    raise result
Exception

 ---> [recv_consumer.py:306 download_files]
2019-07-15 22:14:22 - recv_consumer - 8841 - ERROR : 非法状态 ---> [recv_consumer.py:789 process_tasks]
2019-07-15 22:14:22 - recv_consumer - 8841 - ERROR : 不关心的状态 ---> [recv_consumer.py:818 process_tasks]
2019-07-15 22:15:07 - recv_consumer - 8841 - ERROR : 
Traceback (most recent call last):
  File "/home/zzc/docker_test/app/fq-trainbox/fq_task_recv/DockerApp/recv_consumer.py", line 300, in download_files
    info = self.client.get_task_info(self.task['id'])
  File "/home/zzc/anaconda3/envs/python3.6/lib/python3.6/site-packages/mock/mock.py", line 1092, in __call__
    return _mock_self._mock_call(*args, **kwargs)
  File "/home/zzc/anaconda3/envs/python3.6/lib/python3.6/site-packages/mock/mock.py", line 1147, in _mock_call
    raise result
Exception

 ---> [recv_consumer.py:306 download_files]
2019-07-15 22:17:18 - recv_producer - 8841 - ERROR : 
Traceback (most recent call last):
  File "/home/zzc/docker_test/app/fq-trainbox/fq_task_recv/DockerApp/recv_producer.py", line 102, in request_for_tasks
    devices = self.client.get_server_list()
  File "/home/zzc/anaconda3/envs/python3.6/lib/python3.6/site-packages/mock/mock.py", line 1092, in __call__
    return _mock_self._mock_call(*args, **kwargs)
  File "/home/zzc/anaconda3/envs/python3.6/lib/python3.6/site-packages/mock/mock.py", line 1143, in _mock_call
    raise effect
Exception

 ---> [recv_producer.py:106 request_for_tasks]
2019-07-15 22:17:18 - recv_producer - 8841 - ERROR : 
Traceback (most recent call last):
  File "/home/zzc/docker_test/app/fq-trainbox/fq_task_recv/DockerApp/recv_producer.py", line 102, in request_for_tasks
    devices = self.client.get_server_list()
  File "/home/zzc/anaconda3/envs/python3.6/lib/python3.6/site-packages/mock/mock.py", line 1092, in __call__
    return _mock_self._mock_call(*args, **kwargs)
  File "/home/zzc/anaconda3/envs/python3.6/lib/python3.6/site-packages/mock/mock.py", line 1143, in _mock_call
    raise effect
Exception

 ---> [recv_producer.py:106 request_for_tasks]
2019-07-15 22:17:18 - recv_producer - 8841 - ERROR : 
Traceback (most recent call last):
  File "/home/zzc/docker_test/app/fq-trainbox/fq_task_recv/DockerApp/recv_producer.py", line 102, in request_for_tasks
    devices = self.client.get_server_list()
  File "/home/zzc/anaconda3/envs/python3.6/lib/python3.6/site-packages/mock/mock.py", line 1092, in __call__
    return _mock_self._mock_call(*args, **kwargs)
  File "/home/zzc/anaconda3/envs/python3.6/lib/python3.6/site-packages/mock/mock.py", line 1143, in _mock_call
    raise effect
Exception

 ---> [recv_producer.py:106 request_for_tasks]
2019-07-15 22:17:18 - recv_producer - 8841 - ERROR : 设备请求失败--->无法获取任务 ---> [recv_producer.py:110 request_for_tasks]
